Workbook

Sheet Petunjuk
A1: Kunci Jawaban: Laporan Laba Rugi dari Jurnal Umum
A2: Latihan 16 dari 104 | Tingkat: Lanjutan | Perkiraan waktu: 70 menit | pushexcel.github.io/Pushexcel
A4: Skenario
A5: Kamu staf akuntansi di CV Sumber Niaga. Dari buku jurnal umum triwulan III 2026 (Juli sampai September), kamu menyusun laporan laba rugi. Nama dan kelompok akun diambil dari daftar akun di sheet Acuan. Pendapatan bersaldo normal di kredit, sedangkan HPP dan beban bersaldo normal di debit. Retur penjualan adalah akun pendapatan yang bersaldo di debit, jadi mengurangi pendapatan.
A7: Cara memakai kunci
A8: 1. | B8: Sel hijau berisi rumus kunci yang sudah dihitung. Klik sel untuk melihat rumusnya.
A9: 2. | B9: Kolom Rumus kunci di bawah menampilkan rumus untuk baris pertama atau tiap sel jawaban.
A10: 3. | B10: Rumus ditulis dengan titik koma (;). Ganti dengan koma (,) bila Excel kamu berbahasa Inggris.
A11: 4. | B11: Jawaban lain yang benar secara logika juga boleh, selama hasilnya sama.
A13: Arti warna
B14: Judul kolom data yang sudah diberikan
B15: Judul kolom hasil hitung
B16: Sel berisi rumus kunci
B17: Angka berwarna biru pada blok Parameter = nilai tetap yang boleh dirujuk
A19: Daftar soal
A20: No | B20: Soal | C20: Jawab di | D20: Rumus kunci
A21: 1 | B21: Ambil nama akun dari daftar akun di sheet Acuan berdasarkan Kode Akun. | C21: Sheet Data, kolom H (Nama Akun), baris 2 sampai 49 | D21: =VLOOKUP(D2;Acuan!$A$2:$C$12;2;FALSE)
A22: 2 | B22: Ambil kelompok akun dengan cara yang sama. Perhatikan nomor kolomnya. | C22: Sheet Data, kolom I (Kelompok), baris 2 sampai 49 | D22: =VLOOKUP(D2;Acuan!$A$2:$C$12;3;FALSE)
A23: 3 | B23: Ambil nomor bulan dari tanggal transaksi. | C23: Sheet Data, kolom J (Bulan), baris 2 sampai 49 | D23: =MONTH(B2)
A24: 4 | B24: Hitung saldo normal: untuk Pendapatan = kredit dikurangi debit, untuk kelompok lain = debit dikurangi kredit. | C24: Sheet Data, kolom K (Saldo Normal), baris 2 sampai 49 | D24: =IF(I2="Pendapatan";G2-F2;F2-G2)
A25: 5 | B25: Pada sheet Acuan, hitung total saldo tiap akun dari seluruh jurnal. | C25: Sheet Acuan, kolom D (Total Saldo Akun), baris 2 sampai 12 | D25: =SUMIF(Data!$D$2:$D$49;A2;Data!$K$2:$K$49)
A26: 6 | B26: Berapa total pendapatan bersih (sudah dikurangi retur) triwulan ini? | C26: Sheet Ringkasan, sel C4 | D26: =SUMIF(Data!$I$2:$I$49;"Pendapatan";Data!$K$2:$K$49)
A27: 7 | B27: Berapa total harga pokok penjualan (HPP)? | C27: Sheet Ringkasan, sel C5 | D27: =SUMIF(Data!$I$2:$I$49;"HPP";Data!$K$2:$K$49)
A28: 8 | B28: Berapa laba kotor? (pendapatan bersih dikurangi HPP) | C28: Sheet Ringkasan, sel C6 | D28: =SUMIF(Data!$I$2:$I$49;"Pendapatan";Data!$K$2:$K$49)-SUMIF(Data!$I$2:$I$49;"HPP";Data!$K$2:$K$49)
A29: 9 | B29: Berapa total beban operasional? | C29: Sheet Ringkasan, sel C7 | D29: =SUMIF(Data!$I$2:$I$49;"Beban";Data!$K$2:$K$49)
A30: 10 | B30: Berapa laba bersih triwulan ini? (laba kotor dikurangi beban) | C30: Sheet Ringkasan, sel C8 | D30: =SUMIF(Data!$I$2:$I$49;"Pendapatan";Data!$K$2:$K$49)-SUMIF(Data!$I$2:$I$49;"HPP";Data!$K$2:$K$49)-SUMIF(Data!$I$2:$I$49;"Beban";Data!$K$2:$K$49)
A31: 11 | B31: Berapa margin laba bersih (laba bersih dibagi pendapatan bersih)? | C31: Sheet Ringkasan, sel C9 | D31: =(SUMIF(Data!$I$2:$I$49;"Pendapatan";Data!$K$2:$K$49)-SUMIF(Data!$I$2:$I$49;"HPP";Data!$K$2:$K$49)-SUMIF(Data!$I$2:$I$49;"Beban";Data!$K$2:$K$49))/SUMIF(Data!$I$2:$I$49;"Pendapatan";Data!$K$2:$K$49)
... A34: 14 | B34: Berapa kali terjadi transaksi retur penjualan (kode akun 4103)? | C34: Sheet Ringkasan, sel C12 | D34: =COUNTIF(Data!$D$2:$D$49;4103)

Sheet Data
A1: No | B1: Tanggal | C1: No. Bukti | D1: Kode Akun | E1: Keterangan | F1: Debit | G1: Kredit | H1: Nama Akun | I1: Kelompok | J1: Bulan | K1: Saldo Normal
A2: 1 | B2: 46207 | C2: JU-001 | D2: 4101 | E2: Penjualan barang ke pelanggan | G2: 87500000 | H2: =VLOOKUP(D2,Acuan!$A$2:$C$12,2,FALSE()) -> Penjualan Barang | I2: =VLOOKUP(D2,Acuan!$A$2:$C$12,3,FALSE()) -> Pendapatan | J2: =MONTH(B2) -> 7 | K2: =IF(I2="Pendapatan",G2-F2,F2-G2) -> 87500000
A3: 2 | B3: 46207 | C3: JU-002 | D3: 6103 | E3: Pembayaran listrik dan air | F3: 2500000 | H3: =VLOOKUP(D3,Acuan!$A$2:$C$12,2,FALSE()) -> Beban Listrik dan Air | I3: =VLOOKUP(D3,Acuan!$A$2:$C$12,3,FALSE()) -> Beban | J3: =MONTH(B3) -> 7 | K3: =IF(I3="Pendapatan",G3-F3,F3-G3) -> 2500000
A4: 3 | B4: 46208 | C4: JU-003 | D4: 5102 | E4: Biaya angkut pembelian | F4: 2000000 | H4: =VLOOKUP(D4,Acuan!$A$2:$C$12,2,FALSE()) -> Biaya Angkut Pembelian | I4: =VLOOKUP(D4,Acuan!$A$2:$C$12,3,FALSE()) -> HPP | J4: =MONTH(B4) -> 7 | K4: =IF(I4="Pendapatan",G4-F4,F4-G4) -> 2000000
A5: 4 | B5: 46208 | C5: JU-004 | D5: 6102 | E5: Pembayaran sewa kantor | F5: 6000000 | H5: =VLOOKUP(D5,Acuan!$A$2:$C$12,2,FALSE()) -> Beban Sewa | I5: =VLOOKUP(D5,Acuan!$A$2:$C$12,3,FALSE()) -> Beban | J5: =MONTH(B5) -> 7 | K5: =IF(I5="Pendapatan",G5-F5,F5-G5) -> 6000000
A6: 5 | B6: 46209 | C6: JU-005 | D6: 6104 | E6: Biaya transportasi dinas | F6: 500000 | H6: =VLOOKUP(D6,Acuan!$A$2:$C$12,2,FALSE()) -> Beban Transportasi | I6: =VLOOKUP(D6,Acuan!$A$2:$C$12,3,FALSE()) -> Beban | J6: =MONTH(B6) -> 7 | K6: =IF(I6="Pendapatan",G6-F6,F6-G6) -> 500000
A7: 6 | B7: 46211 | C7: JU-006 | D7: 4101 | E7: Penjualan barang ke pelanggan | G7: 80500000 | H7: =VLOOKUP(D7,Acuan!$A$2:$C$12,2,FALSE()) -> Penjualan Barang | I7: =VLOOKUP(D7,Acuan!$A$2:$C$12,3,FALSE()) -> Pendapatan | J7: =MONTH(B7) -> 7 | K7: =IF(I7="Pendapatan",G7-F7,F7-G7) -> 80500000
A8: 7 | B8: 46212 | C8: JU-007 | D8: 5101 | E8: Pembelian barang dagang dari pemasok | F8: 36500000 | H8: =VLOOKUP(D8,Acuan!$A$2:$C$12,2,FALSE()) -> Pembelian Barang Dagang | I8: =VLOOKUP(D8,Acuan!$A$2:$C$12,3,FALSE()) -> HPP | J8: =MONTH(B8) -> 7 | K8: =IF(I8="Pendapatan",G8-F8,F8-G8) -> 36500000
A9: 8 | B9: 46220 | C9: JU-008 | D9: 5101 | E9: Pembelian barang dagang dari pemasok | F9: 35000000 | H9: =VLOOKUP(D9,Acuan!$A$2:$C$12,2,FALSE()) -> Pembelian Barang Dagang | I9: =VLOOKUP(D9,Acuan!$A$2:$C$12,3,FALSE()) -> HPP | J9: =MONTH(B9) -> 7 | K9: =IF(I9="Pendapatan",G9-F9,F9-G9) -> 35000000
A10: 9 | B10: 46222 | C10: JU-009 | D10: 4103 | E10: Retur penjualan dari pelanggan | F10: 1000000 | H10: =VLOOKUP(D10,Acuan!$A$2:$C$12,2,FALSE()) -> Retur Penjualan | I10: =VLOOKUP(D10,Acuan!$A$2:$C$12,3,FALSE()) -> Pendapatan | J10: =MONTH(B10) -> 7 | K10: =IF(I10="Pendapatan",G10-F10,F10-G10) -> -1000000
A11: 10 | B11: 46224 | C11: JU-010 | D11: 6104 | E11: Biaya transportasi dinas | F11: 1000000 | H11: =VLOOKUP(D11,Acuan!$A$2:$C$12,2,FALSE()) -> Beban Transportasi | I11: =VLOOKUP(D11,Acuan!$A$2:$C$12,3,FALSE()) -> Beban | J11: =MONTH(B11) -> 7 | K11: =IF(I11="Pendapatan",G11-F11,F11-G11) -> 1000000
A12: 11 | B12: 46226 | C12: JU-011 | D12: 6105 | E12: Pembelian perlengkapan kantor | F12: 1500000 | H12: =VLOOKUP(D12,Acuan!$A$2:$C$12,2,FALSE()) -> Beban Perlengkapan | I12: =VLOOKUP(D12,Acuan!$A$2:$C$12,3,FALSE()) -> Beban | J12: =MONTH(B12) -> 7 | K12: =IF(I12="Pendapatan",G12-F12,F12-G12) -> 1500000
A13: 12 | B13: 46228 | C13: JU-012 | D13: 6101 | E13: Pembayaran gaji karyawan | F13: 29000000 | H13: =VLOOKUP(D13,Acuan!$A$2:$C$12,2,FALSE()) -> Beban Gaji | I13: =VLOOKUP(D13,Acuan!$A$2:$C$12,3,FALSE()) -> Beban | J13: =MONTH(B13) -> 7 | K13: =IF(I13="Pendapatan",G13-F13,F13-G13) -> 29000000
A14: 13 | B14: 46229 | C14: JU-013 | D14: 5101 | E14: Pembelian barang dagang dari pemasok | F14: 39000000 | H14: =VLOOKUP(D14,Acuan!$A$2:$C$12,2,FALSE()) -> Pembelian Barang Dagang | I14: =VLOOKUP(D14,Acuan!$A$2:$C$12,3,FALSE()) -> HPP | J14: =MONTH(B14) -> 7 | K14: =IF(I14="Pendapatan",G14-F14,F14-G14) -> 39000000
A15: 14 | B15: 46231 | C15: JU-014 | D15: 4101 | E15: Penjualan barang ke pelanggan | G15: 63500000 | H15: =VLOOKUP(D15,Acuan!$A$2:$C$12,2,FALSE()) -> Penjualan Barang | I15: =VLOOKUP(D15,Acuan!$A$2:$C$12,3,FALSE()) -> Pendapatan | J15: =MONTH(B15) -> 7 | K15: =IF(I15="Pendapatan",G15-F15,F15-G15) -> 63500000
A16: 15 | B16: 46231 | C16: JU-015 | D16: 4102 | E16: Pendapatan jasa pemasangan | G16: 19000000 | H16: =VLOOKUP(D16,Acuan!$A$2:$C$12,2,FALSE()) -> Pendapatan Jasa | I16: =VLOOKUP(D16,Acuan!$A$2:$C$12,3,FALSE()) -> Pendapatan | J16: =MONTH(B16) -> 7 | K16: =IF(I16="Pendapatan",G16-F16,F16-G16) -> 19000000
A17: 16 | B17: 46231 | C17: JU-016 | D17: 6106 | E17: Penyusutan aset bulan berjalan | F17: 2500000 | H17: =VLOOKUP(D17,Acuan!$A$2:$C$12,2,FALSE()) -> Beban Penyusutan | I17: =VLOOKUP(D17,Acuan!$A$2:$C$12,3,FALSE()) -> Beban | J17: =MONTH(B17) -> 7 | K17: =IF(I17="Pendapatan",G17-F17,F17-G17) -> 2500000
A18: 17 | B18: 46237 | C18: JU-017 | D18: 5101 | E18: Pembelian barang dagang dari pemasok | F18: 37500000 | H18: =VLOOKUP(D18,Acuan!$A$2:$C$12,2,FALSE()) -> Pembelian Barang Dagang | I18: =VLOOKUP(D18,Acuan!$A$2:$C$12,3,FALSE()) -> HPP | J18: =MONTH(B18) -> 8 | K18: =IF(I18="Pendapatan",G18-F18,F18-G18) -> 37500000
A19: 18 | B19: 46238 | C19: JU-018 | D19: 6103 | E19: Pembayaran listrik dan air | F19: 2000000 | H19: =VLOOKUP(D19,Acuan!$A$2:$C$12,2,FALSE()) -> Beban Listrik dan Air | I19: =VLOOKUP(D19,Acuan!$A$2:$C$12,3,FALSE()) -> Beban | J19: =MONTH(B19) -> 8 | K19: =IF(I19="Pendapatan",G19-F19,F19-G19) -> 2000000
A20: 19 | B20: 46239 | C20: JU-019 | D20: 6102 | E20: Pembayaran sewa kantor | F20: 6000000 | H20: =VLOOKUP(D20,Acuan!$A$2:$C$12,2,FALSE()) -> Beban Sewa | I20: =VLOOKUP(D20,Acuan!$A$2:$C$12,3,FALSE()) -> Beban | J20: =MONTH(B20) -> 8 | K20: =IF(I20="Pendapatan",G20-F20,F20-G20) -> 6000000
A21: 20 | B21: 46239 | C21: JU-020 | D21: 6105 | E21: Pembelian perlengkapan kantor | F21: 1500000 | H21: =VLOOKUP(D21,Acuan!$A$2:$C$12,2,FALSE()) -> Beban Perlengkapan | I21: =VLOOKUP(D21,Acuan!$A$2:$C$12,3,FALSE()) -> Beban | J21: =MONTH(B21) -> 8 | K21: =IF(I21="Pendapatan",G21-F21,F21-G21) -> 1500000
A22: 21 | B22: 46241 | C22: JU-021 | D22: 6104 | E22: Biaya transportasi dinas | F22: 500000 | H22: =VLOOKUP(D22,Acuan!$A$2:$C$12,2,FALSE()) -> Beban Transportasi | I22: =VLOOKUP(D22,Acuan!$A$2:$C$12,3,FALSE()) -> Beban | J22: =MONTH(B22) -> 8 | K22: =IF(I22="Pendapatan",G22-F22,F22-G22) -> 500000
A23: 22 | B23: 46246 | C23: JU-022 | D23: 4101 | E23: Penjualan barang ke pelanggan | G23: 41500000 | H23: =VLOOKUP(D23,Acuan!$A$2:$C$12,2,FALSE()) -> Penjualan Barang | I23: =VLOOKUP(D23,Acuan!$A$2:$C$12,3,FALSE()) -> Pendapatan | J23: =MONTH(B23) -> 8 | K23: =IF(I23="Pendapatan",G23-F23,F23-G23) -> 41500000
A24: 23 | B24: 46249 | C24: JU-023 | D24: 5102 | E24: Biaya angkut pembelian | F24: 3000000 | H24: =VLOOKUP(D24,Acuan!$A$2:$C$12,2,FALSE()) -> Biaya Angkut Pembelian | I24: =VLOOKUP(D24,Acuan!$A$2:$C$12,3,FALSE()) -> HPP | J24: =MONTH(B24) -> 8 | K24: =IF(I24="Pendapatan",G24-F24,F24-G24) -> 3000000
A25: 24 | B25: 46252 | C25: JU-024 | D25: 5101 | E25: Pembelian barang dagang dari pemasok | F25: 30000000 | H25: =VLOOKUP(D25,Acuan!$A$2:$C$12,2,FALSE()) -> Pembelian Barang Dagang | I25: =VLOOKUP(D25,Acuan!$A$2:$C$12,3,FALSE()) -> HPP | J25: =MONTH(B25) -> 8 | K25: =IF(I25="Pendapatan",G25-F25,F25-G25) -> 30000000
A26: 25 | B26: 46252 | C26: JU-025 | D26: 6104 | E26: Biaya transportasi dinas | F26: 500000 | H26: =VLOOKUP(D26,Acuan!$A$2:$C$12,2,FALSE()) -> Beban Transportasi | I26: =VLOOKUP(D26,Acuan!$A$2:$C$12,3,FALSE()) -> Beban | J26: =MONTH(B26) -> 8 | K26: =IF(I26="Pendapatan",G26-F26,F26-G26) -> 500000
A27: 26 | B27: 46255 | C27: JU-026 | D27: 5101 | E27: Pembelian barang dagang dari pemasok | F27: 45500000 | H27: =VLOOKUP(D27,Acuan!$A$2:$C$12,2,FALSE()) -> Pembelian Barang Dagang | I27: =VLOOKUP(D27,Acuan!$A$2:$C$12,3,FALSE()) -> HPP | J27: =MONTH(B27) -> 8 | K27: =IF(I27="Pendapatan",G27-F27,F27-G27) -> 45500000
A28: 27 | B28: 46256 | C28: JU-027 | D28: 4102 | E28: Pendapatan jasa pemasangan | G28: 9000000 | H28: =VLOOKUP(D28,Acuan!$A$2:$C$12,2,FALSE()) -> Pendapatan Jasa | I28: =VLOOKUP(D28,Acuan!$A$2:$C$12,3,FALSE()) -> Pendapatan | J28: =MONTH(B28) -> 8 | K28: =IF(I28="Pendapatan",G28-F28,F28-G28) -> 9000000
A29: 28 | B29: 46258 | C29: JU-028 | D29: 4102 | E29: Pendapatan jasa pemasangan | G29: 18000000 | H29: =VLOOKUP(D29,Acuan!$A$2:$C$12,2,FALSE()) -> Pendapatan Jasa | I29: =VLOOKUP(D29,Acuan!$A$2:$C$12,3,FALSE()) -> Pendapatan | J29: =MONTH(B29) -> 8 | K29: =IF(I29="Pendapatan",G29-F29,F29-G29) -> 18000000
A30: 29 | B30: 46259 | C30: JU-029 | D30: 6101 | E30: Pembayaran gaji karyawan | F30: 28000000 | H30: =VLOOKUP(D30,Acuan!$A$2:$C$12,2,FALSE()) -> Beban Gaji | I30: =VLOOKUP(D30,Acuan!$A$2:$C$12,3,FALSE()) -> Beban | J30: =MONTH(B30) -> 8 | K30: =IF(I30="Pendapatan",G30-F30,F30-G30) -> 28000000
A31: 30 | B31: 46260 | C31: JU-030 | D31: 4101 | E31: Penjualan barang ke pelanggan | G31: 64500000 | H31: =VLOOKUP(D31,Acuan!$A$2:$C$12,2,FALSE()) -> Penjualan Barang | I31: =VLOOKUP(D31,Acuan!$A$2:$C$12,3,FALSE()) -> Pendapatan | J31: =MONTH(B31) -> 8 | K31: =IF(I31="Pendapatan",G31-F31,F31-G31) -> 64500000
A32: 31 | B32: 46262 | C32: JU-031 | D32: 4101 | E32: Penjualan barang ke pelanggan | G32: 82500000 | H32: =VLOOKUP(D32,Acuan!$A$2:$C$12,2,FALSE()) -> Penjualan Barang | I32: =VLOOKUP(D32,Acuan!$A$2:$C$12,3,FALSE()) -> Pendapatan | J32: =MONTH(B32) -> 8 | K32: =IF(I32="Pendapatan",G32-F32,F32-G32) -> 82500000
A33: 32 | B33: 46262 | C33: JU-032 | D33: 6106 | E33: Penyusutan aset bulan berjalan | F33: 2500000 | H33: =VLOOKUP(D33,Acuan!$A$2:$C$12,2,FALSE()) -> Beban Penyusutan | I33: =VLOOKUP(D33,Acuan!$A$2:$C$12,3,FALSE()) -> Beban | J33: =MONTH(B33) -> 8 | K33: =IF(I33="Pendapatan",G33-F33,F33-G33) -> 2500000
A34: 33 | B34: 46266 | C34: JU-033 | D34: 6105 | E34: Pembelian perlengkapan kantor | F34: 500000 | H34: =VLOOKUP(D34,Acuan!$A$2:$C$12,2,FALSE()) -> Beban Perlengkapan | I34: =VLOOKUP(D34,Acuan!$A$2:$C$12,3,FALSE()) -> Beban | J34: =MONTH(B34) -> 9 | K34: =IF(I34="Pendapatan",G34-F34,F34-G34) -> 500000
A35: 34 | B35: 46269 | C35: JU-034 | D35: 4101 | E35: Penjualan barang ke pelanggan | G35: 79500000 | H35: =VLOOKUP(D35,Acuan!$A$2:$C$12,2,FALSE()) -> Penjualan Barang | I35: =VLOOKUP(D35,Acuan!$A$2:$C$12,3,FALSE()) -> Pendapatan | J35: =MONTH(B35) -> 9 | K35: =IF(I35="Pendapatan",G35-F35,F35-G35) -> 79500000
A36: 35 | B36: 46270 | C36: JU-035 | D36: 4101 | E36: Penjualan barang ke pelanggan | G36: 55000000 | H36: =VLOOKUP(D36,Acuan!$A$2:$C$12,2,FALSE()) -> Penjualan Barang | I36: =VLOOKUP(D36,Acuan!$A$2:$C$12,3,FALSE()) -> Pendapatan | J36: =MONTH(B36) -> 9 | K36: =IF(I36="Pendapatan",G36-F36,F36-G36) -> 55000000
A37: 36 | B37: 46270 | C37: JU-036 | D37: 5101 | E37: Pembelian barang dagang dari pemasok | F37: 39500000 | H37: =VLOOKUP(D37,Acuan!$A$2:$C$12,2,FALSE()) -> Pembelian Barang Dagang | I37: =VLOOKUP(D37,Acuan!$A$2:$C$12,3,FALSE()) -> HPP | J37: =MONTH(B37) -> 9 | K37: =IF(I37="Pendapatan",G37-F37,F37-G37) -> 39500000
A38: 37 | B38: 46270 | C38: JU-037 | D38: 6102 | E38: Pembayaran sewa kantor | F38: 6000000 | H38: =VLOOKUP(D38,Acuan!$A$2:$C$12,2,FALSE()) -> Beban Sewa | I38: =VLOOKUP(D38,Acuan!$A$2:$C$12,3,FALSE()) -> Beban | J38: =MONTH(B38) -> 9 | K38: =IF(I38="Pendapatan",G38-F38,F38-G38) -> 6000000
A39: 38 | B39: 46271 | C39: JU-038 | D39: 4103 | E39: Retur penjualan dari pelanggan | F39: 4500000 | H39: =VLOOKUP(D39,Acuan!$A$2:$C$12,2,FALSE()) -> Retur Penjualan | I39: =VLOOKUP(D39,Acuan!$A$2:$C$12,3,FALSE()) -> Pendapatan | J39: =MONTH(B39) -> 9 | K39: =IF(I39="Pendapatan",G39-F39,F39-G39) -> -4500000
A40: 39 | B40: 46272 | C40: JU-039 | D40: 5101 | E40: Pembelian barang dagang dari pemasok | F40: 43500000 | H40: =VLOOKUP(D40,Acuan!$A$2:$C$12,2,FALSE()) -> Pembelian Barang Dagang | I40: =VLOOKUP(D40,Acuan!$A$2:$C$12,3,FALSE()) -> HPP | J40: =MONTH(B40) -> 9 | K40: =IF(I40="Pendapatan",G40-F40,F40-G40) -> 43500000
...

Sheet Acuan
A1: Kode Akun | B1: Nama Akun | C1: Kelompok | D1: Total Saldo Akun
A2: 4101 | B2: Penjualan Barang | C2: Pendapatan | D2: =SUMIF(Data!$D$2:$D$49,A2,Data!$K$2:$K$49) -> 609000000
A3: 4102 | B3: Pendapatan Jasa | C3: Pendapatan | D3: =SUMIF(Data!$D$2:$D$49,A3,Data!$K$2:$K$49) -> 58000000
A4: 4103 | B4: Retur Penjualan | C4: Pendapatan | D4: =SUMIF(Data!$D$2:$D$49,A4,Data!$K$2:$K$49) -> -5500000
A5: 5101 | B5: Pembelian Barang Dagang | C5: HPP | D5: =SUMIF(Data!$D$2:$D$49,A5,Data!$K$2:$K$49) -> 340500000
A6: 5102 | B6: Biaya Angkut Pembelian | C6: HPP | D6: =SUMIF(Data!$D$2:$D$49,A6,Data!$K$2:$K$49) -> 8000000
A7: 6101 | B7: Beban Gaji | C7: Beban | D7: =SUMIF(Data!$D$2:$D$49,A7,Data!$K$2:$K$49) -> 85500000
A8: 6102 | B8: Beban Sewa | C8: Beban | D8: =SUMIF(Data!$D$2:$D$49,A8,Data!$K$2:$K$49) -> 18000000
A9: 6103 | B9: Beban Listrik dan Air | C9: Beban | D9: =SUMIF(Data!$D$2:$D$49,A9,Data!$K$2:$K$49) -> 6000000
A10: 6104 | B10: Beban Transportasi | C10: Beban | D10: =SUMIF(Data!$D$2:$D$49,A10,Data!$K$2:$K$49) -> 6500000
A11: 6105 | B11: Beban Perlengkapan | C11: Beban | D11: =SUMIF(Data!$D$2:$D$49,A11,Data!$K$2:$K$49) -> 3500000
A12: 6106 | B12: Beban Penyusutan | C12: Beban | D12: =SUMIF(Data!$D$2:$D$49,A12,Data!$K$2:$K$49) -> 7500000

Sheet Ringkasan
A1: Ringkasan: lembar jawaban soal berjenis ringkasan
A2: Sel hijau berisi rumus kunci.
A3: No | B3: Pertanyaan | C3: Jawaban | D3: Contoh format hasil
A4: 6 | B4: Total pendapatan bersih | C4: =SUMIF(Data!$I$2:$I$49,"Pendapatan",Data!$K$2:$K$49) -> 661500000 | D4: Rupiah, mis. Rp 600.000.000
A5: 7 | B5: Total HPP | C5: =SUMIF(Data!$I$2:$I$49,"HPP",Data!$K$2:$K$49) -> 348500000 | D5: Rupiah, mis. Rp 320.000.000
A6: 8 | B6: Laba kotor | C6: =SUMIF(Data!$I$2:$I$49,"Pendapatan",Data!$K$2:$K$49)-SUMIF(Data!$I$2:$I$49,"HPP",Data!$K$2:$K$49) -> 313000000 | D6: Rupiah, mis. Rp 280.000.000
A7: 9 | B7: Total beban operasional | C7: =SUMIF(Data!$I$2:$I$49,"Beban",Data!$K$2:$K$49) -> 127000000 | D7: Rupiah, mis. Rp 150.000.000
A8: 10 | B8: Laba bersih | C8: =SUMIF(Data!$I$2:$I$49,"Pendapatan",Data!$K$2:$K$49)-SUMIF(Data!$I$2:$I$49,"HPP",Data!$K$2:$K$49)-SUMIF(Data!$I$2:$I$49,"Beban",Data!$K$2:$K$49) -> 186000000 | D8: Rupiah, mis. Rp 130.000.000
A9: 11 | B9: Margin laba bersih | C9: =(SUMIF(Data!$I$2:$I$49,"Pendapatan",Data!$K$2:$K$49)-SUMIF(Data!$I$2:$I$49,"HPP",Data!$K$2:$K$49)-SUMIF(Data!$I$2:$I$49,"Beban",Data!$K$2:$K$49))/SUMIF(Data!$I$2:$I$49,"Pendapatan",Data!$K$2:$K$49) -> 0.28117914 | D9: Persen, mis. 21,5%
A10: 12 | B10: Pendapatan bersih bulan September | C10: =SUMIFS(Data!$K$2:$K$49,Data!$I$2:$I$49,"Pendapatan",Data!$J$2:$J$49,9) -> 196500000 | D10: Rupiah, mis. Rp 210.000.000
A11: 13 | B11: Akun beban dengan total terbesar | C11: =INDEX(Acuan!$B$2:$B$12,MATCH(SUMPRODUCT(MAX((Acuan!$C$2:$C$12="Beban")*Acuan!$D$2:$D$12)),Acuan!$D$2:$D$12,0)) -> Beban Gaji | D11: Teks: nama akun
A12: 14 | B12: Jumlah transaksi retur penjualan | C12: =COUNTIF(Data!$D$2:$D$49,4103) -> 2 | D12: Angka bulat, mis. 2
